{"uuid": "b45d11ce-ca13-44d0-af66-c4c6bfc53795", "children": ["0ef6f229-ce66-4e6a-84cd-3aa6aee48ec8", "62294ba7-d783-4fc7-ae05-9e3aa339af24", "4f7121a4-88bd-4b4a-9628-7bf20cce6476", "dfe4b396-07c4-48c1-9087-adf5192e164c"], "befores": [{"name": "remote_driver", "status": "broken", "statusDetails": {"message": "urllib3.exceptions.MaxRetryError: HTTPConnectionPool(host='127.0.0.1', port=4444): Max retries exceeded with url: /wd/hub/session (Caused by NewConnectionError('<urllib3.connection.HTTPConnection object at 0x0490CA90>: Failed to establish a new connection: [WinError 10061] 由于目标计算机积极拒绝，无法连接。'))\n", "trace": "  File \"d:\\工具\\python\\lib\\site-packages\\pluggy\\_callers.py\", line 39, in _multicall\n    res = hook_impl.function(*args)\n  File \"d:\\工具\\python\\lib\\site-packages\\_pytest\\fixtures.py\", line 1126, in pytest_fixture_setup\n    result = call_fixture_func(fixturefunc, request, kwargs)\n  File \"d:\\工具\\python\\lib\\site-packages\\_pytest\\fixtures.py\", line 925, in call_fixture_func\n    fixture_result = next(generator)\n  File \"D:\\auto_test\\case\\test_case_pytest.py\", line 28, in remote_driver\n    driver = webdriver.Remote('http://127.0.0.1:4444/wd/hub',desired_caps)\n  File \"d:\\工具\\python\\lib\\site-packages\\selenium\\webdriver\\remote\\webdriver.py\", line 275, in __init__\n    self.start_session(capabilities, browser_profile)\n  File \"d:\\工具\\python\\lib\\site-packages\\selenium\\webdriver\\remote\\webdriver.py\", line 365, in start_session\n    response = self.execute(Command.NEW_SESSION, parameters)\n  File \"d:\\工具\\python\\lib\\site-packages\\selenium\\webdriver\\remote\\webdriver.py\", line 428, in execute\n    response = self.command_executor.execute(driver_command, params)\n  File \"d:\\工具\\python\\lib\\site-packages\\selenium\\webdriver\\remote\\remote_connection.py\", line 347, in execute\n    return self._request(command_info[0], url, body=data)\n  File \"d:\\工具\\python\\lib\\site-packages\\selenium\\webdriver\\remote\\remote_connection.py\", line 369, in _request\n    response = self._conn.request(method, url, body=body, headers=headers)\n  File \"d:\\工具\\python\\lib\\site-packages\\urllib3\\request.py\", line 78, in request\n    return self.request_encode_body(\n  File \"d:\\工具\\python\\lib\\site-packages\\urllib3\\request.py\", line 170, in request_encode_body\n    return self.urlopen(method, url, **extra_kw)\n  File \"d:\\工具\\python\\lib\\site-packages\\urllib3\\poolmanager.py\", line 375, in urlopen\n    response = conn.urlopen(method, u.request_uri, **kw)\n  File \"d:\\工具\\python\\lib\\site-packages\\urllib3\\connectionpool.py\", line 783, in urlopen\n    return self.urlopen(\n  File \"d:\\工具\\python\\lib\\site-packages\\urllib3\\connectionpool.py\", line 783, in urlopen\n    return self.urlopen(\n  File \"d:\\工具\\python\\lib\\site-packages\\urllib3\\connectionpool.py\", line 783, in urlopen\n    return self.urlopen(\n  File \"d:\\工具\\python\\lib\\site-packages\\urllib3\\connectionpool.py\", line 755, in urlopen\n    retries = retries.increment(\n  File \"d:\\工具\\python\\lib\\site-packages\\urllib3\\util\\retry.py\", line 574, in increment\n    raise MaxRetryError(_pool, url, error or ResponseError(cause))\n"}, "start": 1657157457936, "stop": 1657157466102}], "start": 1657157457936, "stop": 1657157469351}