{"uuid": "ec4eb21b-46f7-4337-9e6b-f29b6791554c", "children": ["736f93a9-c5bd-4b82-8ca4-137bd4e15494", "38494700-35c9-4121-8c18-c1eac4117adb", "e9d8a48b-e44a-4c38-ae43-ed5bad0b48e8"], "befores": [{"name": "remote_driver", "status": "broken", "statusDetails": {"message": "urllib3.exceptions.MaxRetryError: HTTPConnectionPool(host='127.0.0.1', port=4444): Max retries exceeded with url: /wd/hub/session (Caused by NewConnectionError('<urllib3.connection.HTTPConnection object at 0x0458B370>: Failed to establish a new connection: [WinError 10061] 由于目标计算机积极拒绝，无法连接。'))\n", "trace": "  File \"d:\\工具\\python\\lib\\site-packages\\pluggy\\_callers.py\", line 39, in _multicall\n    res = hook_impl.function(*args)\n  File \"d:\\工具\\python\\lib\\site-packages\\_pytest\\fixtures.py\", line 1126, in pytest_fixture_setup\n    result = call_fixture_func(fixturefunc, request, kwargs)\n  File \"d:\\工具\\python\\lib\\site-packages\\_pytest\\fixtures.py\", line 925, in call_fixture_func\n    fixture_result = next(generator)\n  File \"D:\\auto_test\\case\\test_case_pytest.py\", line 26, in remote_driver\n    driver = webdriver.Remote('http://127.0.0.1:4444/wd/hub',desired_caps)\n  File \"d:\\工具\\python\\lib\\site-packages\\selenium\\webdriver\\remote\\webdriver.py\", line 275, in __init__\n    self.start_session(capabilities, browser_profile)\n  File \"d:\\工具\\python\\lib\\site-packages\\selenium\\webdriver\\remote\\webdriver.py\", line 365, in start_session\n    response = self.execute(Command.NEW_SESSION, parameters)\n  File \"d:\\工具\\python\\lib\\site-packages\\selenium\\webdriver\\remote\\webdriver.py\", line 428, in execute\n    response = self.command_executor.execute(driver_command, params)\n  File \"d:\\工具\\python\\lib\\site-packages\\selenium\\webdriver\\remote\\remote_connection.py\", line 347, in execute\n    return self._request(command_info[0], url, body=data)\n  File \"d:\\工具\\python\\lib\\site-packages\\selenium\\webdriver\\remote\\remote_connection.py\", line 369, in _request\n    response = self._conn.request(method, url, body=body, headers=headers)\n  File \"d:\\工具\\python\\lib\\site-packages\\urllib3\\request.py\", line 78, in request\n    return self.request_encode_body(\n  File \"d:\\工具\\python\\lib\\site-packages\\urllib3\\request.py\", line 170, in request_encode_body\n    return self.urlopen(method, url, **extra_kw)\n  File \"d:\\工具\\python\\lib\\site-packages\\urllib3\\poolmanager.py\", line 375, in urlopen\n    response = conn.urlopen(method, u.request_uri, **kw)\n  File \"d:\\工具\\python\\lib\\site-packages\\urllib3\\connectionpool.py\", line 783, in urlopen\n    return self.urlopen(\n  File \"d:\\工具\\python\\lib\\site-packages\\urllib3\\connectionpool.py\", line 783, in urlopen\n    return self.urlopen(\n  File \"d:\\工具\\python\\lib\\site-packages\\urllib3\\connectionpool.py\", line 783, in urlopen\n    return self.urlopen(\n  File \"d:\\工具\\python\\lib\\site-packages\\urllib3\\connectionpool.py\", line 755, in urlopen\n    retries = retries.increment(\n  File \"d:\\工具\\python\\lib\\site-packages\\urllib3\\util\\retry.py\", line 574, in increment\n    raise MaxRetryError(_pool, url, error or ResponseError(cause))\n"}, "start": 1656914404313, "stop": 1656914412462}], "start": 1656914404313, "stop": 1656914413679}